Workbook

Sheet ChlaCalc
A1: Chlorophyll a by Fluorimetry: | E1: Range: FI | F1: <1 to 640.93 | G1: LSS 1 | H1: LSS 2 | I1: LSS 3 | J1: LSS 4 | K1: LSS 5
A2: 2017 Standards Mar 1 2017 | E2: Slope | F2: 0.025 | G2: 22.958 | H2: 23.242 | I2: 23.437 | J2: 23.465 | L2: LSS MEAN | M2: =AVERAGE(G2,H2,I2,J2,K2,K4,J4,I4,H4,G4) -> 23.2755
A3: Date extracted: | G3: LSS 6 | H3: LSS 7 | I3: LSS 8 | J3: LSS 9 | K3: LSS 10
A4: Date analyzed:
A5: Analyst: | E5: Intercept | F5: 0.2152
A6: Client:
A7: Sample ID. | C7: Filtered | D7: Volume | E7: FI | F7: FI/LSS | G7: Dil'n | H7: Chl a | I7: Final Conc'n | J7: Mean | K7: S.D. | L7: R.S.D
C8: Volume | D8: EtOH | H8: Filter | J8: Conc'n
C9: (L) | D9: (mL) | H9: (µg) | I9: (µg/L) | J9: (µg/L) | K9: (µg/L) | L9: (%)
A10: StonyCreek-071017 | C10: 0.04 | D10: 14 | E10: 2.469 | F10: =E10/$M$2 -> 0.10607721 | G10: 1 | H10: =((((F10-$F$5)/$F$2)/1000)*D10) -> -0.061108765 | I10: =((H10/C10)*G10) -> -1.5277191
A11: StonyCreek-071017-DUP | C11: 0.031 | D11: 14 | E11: 2.267 | F11: =E11/$M$2 -> 0.097398552 | G11: 1 | H11: =((((F11-$F$5)/$F$2)/1000)*D11) -> -0.065968811 | I11: =((H11/C11)*G11) -> -2.1280262
A12: 27-SS02LU-071217 | C12: 2.13 | D12: 14 | E12: 34.929 | F12: =E12/$M$2 -> 1.5006767 | G12: 1 | H12: =((((F12-$F$5)/$F$2)/1000)*D12) -> 0.71986694 | I12: =((H12/C12)*G12) -> 0.3379657
A13: 48-SS08LI-071217 | C13: 0.002 | D13: 14 | E13: 2.7 | F13: =E13/$M$2 -> 0.1160018 | G13: 1 | H13: =((((F13-$F$5)/$F$2)/1000)*D13) -> -0.055550989 | I13: =((H13/C13)*G13) -> -27.775495
A14: 13-SS02MU-071317 | C14: 0.415 | D14: 14 | E14: 8.935 | F14: =E14/$M$2 -> 0.38388005 | G14: 1 | H14: =((((F14-$F$5)/$F$2)/1000)*D14) -> 0.094460826 | I14: =((H14/C14)*G14) -> 0.22761645
A15: 26-SS01LU-071417 | C15: 3 | D15: 14 | E15: 5.073 | F15: =E15/$M$2 -> 0.2179545 | G15: 1 | H15: =((((F15-$F$5)/$F$2)/1000)*D15) -> 0.0015425208 | I15: =((H15/C15)*G15) -> 0.00051417362
A16: 30-SS01FU-071417 | C16: 2.475 | D16: 14 | E16: 21.775 | F16: =E16/$M$2 -> 0.93553307 | G16: 1 | H16: =((((F16-$F$5)/$F$2)/1000)*D16) -> 0.40338652 | I16: =((H16/C16)*G16) -> 0.16298445
A17: 42-SS01BI-071517 | C17: 0.01 | D17: 14 | E17: 2.868 | F17: =E17/$M$2 -> 0.12321969 | G17: 1 | H17: =((((F17-$F$5)/$F$2)/1000)*D17) -> -0.051508971 | I17: =((H17/C17)*G17) -> -5.1508971
A18: 42-SS01BI-071517 - DUP | C18: 0.01 | D18: 14 | E18: 2.398 | F18: =E18/$M$2 -> 0.10302679 | G18: 1 | H18: =((((F18-$F$5)/$F$2)/1000)*D18) -> -0.062816999 | I18: =((H18/C18)*G18) -> -6.2816999
A19: 53-SS01LU-alt2-071517 | C19: 6.925 | D19: 14 | E19: 53.166 | F19: =E19/$M$2 -> 2.2842044 | G19: 1 | H19: =((((F19-$F$5)/$F$2)/1000)*D19) -> 1.1586425 | I19: =((H19/C19)*G19) -> 0.16731299
A20: 0-SS02BI-071717 | C20: 0.0008 | D20: 14 | E20: 6.194 | F20: =E20/$M$2 -> 0.26611673 | G20: 1 | H20: =((((F20-$F$5)/$F$2)/1000)*D20) -> 0.02851337 | I20: =((H20/C20)*G20) -> 35.641713
A21: 6-SS02MI-071717 | C21: 0.79 | D21: 14 | E21: 4.924 | F21: =E21/$M$2 -> 0.21155292 | G21: 1 | H21: =((((F21-$F$5)/$F$2)/1000)*D21) -> -0.0020423645 | I21: =((H21/C21)*G21) -> -0.0025852716
... A58: 40-SS02BU-alt1-080917 | C58: 1.5 | D58: 14 | E58: 7.343 | F58: =E58/$M$2 -> 0.31548194 | G58: 1 | H58: =((((F58-$F$5)/$F$2)/1000)*D58) -> 0.056157889 | I58: =((H58/C58)*G58) -> 0.037438593
D60: 14 | F60: =E60/$M$2 -> 0 | G60: 1 | H60: =((((F60-$F$5)/$F$2)/1000)*D60) -> -0.120512 | I60: =((H60/C60)*G60) -> #DIV/0! | J60: =AVERAGE(I60:I61) -> #DIV/0! | K60: =STDEV(I60:I61) -> #DIV/0! | L60: =K60/J60 -> #DIV/0!
D61: 14 | F61: =E61/$M$2 -> 0 | G61: 1 | H61: =((((F61-$F$5)/$F$2)/1000)*D61) -> -0.120512 | I61: =((H61/C61)*G61) -> #DIV/0!
D62: 14 | F62: =E62/$M$2 -> 0 | G62: 1 | H62: =((((F62-$F$5)/$F$2)/1000)*D62) -> -0.120512 | I62: =((H62/C62)*G62) -> #DIV/0! | J62: =AVERAGE(I62:I63) -> #DIV/0! | K62: =STDEV(I62:I63) -> #DIV/0! | L62: =K62/J62 -> #DIV/0!
D63: 14 | F63: =E63/$M$2 -> 0 | G63: 1 | H63: =((((F63-$F$5)/$F$2)/1000)*D63) -> -0.120512 | I63: =((H63/C63)*G63) -> #DIV/0!
D64: 14 | F64: =E64/$M$2 -> 0 | G64: 1 | H64: =((((F64-$F$5)/$F$2)/1000)*D64) -> -0.120512 | I64: =((H64/C64)*G64) -> #DIV/0! | J64: =AVERAGE(I64:I65) -> #DIV/0! | K64: =STDEV(I64:I65) -> #DIV/0! | L64: =K64/J64 -> #DIV/0!
D65: 14 | F65: =E65/$M$2 -> 0 | G65: 1 | H65: =((((F65-$F$5)/$F$2)/1000)*D65) -> -0.120512 | I65: =((H65/C65)*G65) -> #DIV/0!
D66: 14 | F66: =E66/$M$2 -> 0 | G66: 1 | H66: =((((F66-$F$5)/$F$2)/1000)*D66) -> -0.120512 | I66: =((H66/C66)*G66) -> #DIV/0! | J66: =AVERAGE(I66:I67) -> #DIV/0! | K66: =STDEV(I66:I67) -> #DIV/0! | L66: =K66/J66 -> #DIV/0!
D67: 14 | F67: =E67/$M$2 -> 0 | G67: 1 | H67: =((((F67-$F$5)/$F$2)/1000)*D67) -> -0.120512 | I67: =((H67/C67)*G67) -> #DIV/0!
D68: 14 | F68: =E68/$M$2 -> 0 | G68: 1 | H68: =((((F68-$F$5)/$F$2)/1000)*D68) -> -0.120512 | I68: =((H68/C68)*G68) -> #DIV/0! | J68: =AVERAGE(I68:I69) -> #DIV/0! | K68: =STDEV(I68:I69) -> #DIV/0! | L68: =K68/J68 -> #DIV/0!
D69: 14 | F69: =E69/$M$2 -> 0 | G69: 1 | H69: =((((F69-$F$5)/$F$2)/1000)*D69) -> -0.120512 | I69: =((H69/C69)*G69) -> #DIV/0!
D70: 14 | F70: =E70/$M$2 -> 0 | G70: 1 | H70: =((((F70-$F$5)/$F$2)/1000)*D70) -> -0.120512 | I70: =((H70/C70)*G70) -> #DIV/0! | J70: =AVERAGE(I70:I71) -> #DIV/0! | K70: =STDEV(I70:I71) -> #DIV/0! | L70: =K70/J70 -> #DIV/0!
D71: 14 | F71: =E71/$M$2 -> 0 | G71: 1 | H71: =((((F71-$F$5)/$F$2)/1000)*D71) -> -0.120512 | I71: =((H71/C71)*G71) -> #DIV/0!
D72: 14 | F72: =E72/$M$2 -> 0 | G72: 1 | H72: =((((F72-$F$5)/$F$2)/1000)*D72) -> -0.120512 | I72: =((H72/C72)*G72) -> #DIV/0! | J72: =AVERAGE(I72:I73) -> #DIV/0! | K72: =STDEV(I72:I73) -> #DIV/0! | L72: =K72/J72 -> #DIV/0!
D73: 14 | F73: =E73/$M$2 -> 0 | G73: 1 | H73: =((((F73-$F$5)/$F$2)/1000)*D73) -> -0.120512 | I73: =((H73/C73)*G73) -> #DIV/0!
D74: 14 | F74: =E74/$M$2 -> 0 | G74: 1 | H74: =((((F74-$F$5)/$F$2)/1000)*D74) -> -0.120512 | I74: =((H74/C74)*G74) -> #DIV/0! | J74: =AVERAGE(I74:I75) -> #DIV/0! | K74: =STDEV(I74:I75) -> #DIV/0! | L74: =K74/J74 -> #DIV/0!
D75: 14 | F75: =E75/$M$2 -> 0 | G75: 1 | H75: =((((F75-$F$5)/$F$2)/1000)*D75) -> -0.120512 | I75: =((H75/C75)*G75) -> #DIV/0!
D76: 14 | F76: =E76/$M$2 -> 0 | G76: 1 | H76: =((((F76-$F$5)/$F$2)/1000)*D76) -> -0.120512 | I76: =((H76/C76)*G76) -> #DIV/0! | J76: =AVERAGE(I76:I77) -> #DIV/0! | K76: =STDEV(I76:I77) -> #DIV/0! | L76: =K76/J76 -> #DIV/0!
D77: 14 | F77: =E77/$M$2 -> 0 | G77: 1 | H77: =((((F77-$F$5)/$F$2)/1000)*D77) -> -0.120512 | I77: =((H77/C77)*G77) -> #DIV/0!
...

Sheet forR
A1: samplecode | B1: filteredvol_L | C1: chlafilter_ug | D1: finalconc_ugL | E1: site | F1: date | G1: samptype
A2: =ChlaCalc!A10 -> StonyCreek-071017 | B2: =ChlaCalc!C10 -> 0.04 | C2: =ChlaCalc!H10 -> -0.061108765 | D2: =ChlaCalc!I10 -> -1.5277191 | E2: SC Outlet | F2: 42926 | G2: Sample
A3: =ChlaCalc!A11 -> StonyCreek-071017-DUP | B3: =ChlaCalc!C11 -> 0.031 | C3: =ChlaCalc!H11 -> -0.065968811 | D3: =ChlaCalc!I11 -> -2.1280262 | E3: SC Outlet | F3: 42926 | G3: Duplicate
A4: =ChlaCalc!A12 -> 27-SS02LU-071217 | B4: =ChlaCalc!C12 -> 2.13 | C4: =ChlaCalc!H12 -> 0.71986694 | D4: =ChlaCalc!I12 -> 0.3379657 | E4: 27 | F4: 42928 | G4: Sample
A5: =ChlaCalc!A13 -> 48-SS08LI-071217 | B5: =ChlaCalc!C13 -> 0.002 | C5: =ChlaCalc!H13 -> -0.055550989 | D5: =ChlaCalc!I13 -> -27.775495 | E5: 48 | F5: 42928 | G5: Sample
A6: =ChlaCalc!A14 -> 13-SS02MU-071317 | B6: =ChlaCalc!C14 -> 0.415 | C6: =ChlaCalc!H14 -> 0.094460826 | D6: =ChlaCalc!I14 -> 0.22761645 | E6: 13 | F6: 42929 | G6: Sample
A7: =ChlaCalc!A15 -> 26-SS01LU-071417 | B7: =ChlaCalc!C15 -> 3 | C7: =ChlaCalc!H15 -> 0.0015425208 | D7: =ChlaCalc!I15 -> 0.00051417362 | E7: 26 | F7: 42930 | G7: Sample
A8: =ChlaCalc!A16 -> 30-SS01FU-071417 | B8: =ChlaCalc!C16 -> 2.475 | C8: =ChlaCalc!H16 -> 0.40338652 | D8: =ChlaCalc!I16 -> 0.16298445 | E8: 30 | F8: 42930 | G8: Sample
A9: =ChlaCalc!A17 -> 42-SS01BI-071517 | B9: =ChlaCalc!C17 -> 0.01 | C9: =ChlaCalc!H17 -> -0.051508971 | D9: =ChlaCalc!I17 -> -5.1508971 | E9: 42 | F9: 42931 | G9: Sample
A10: =ChlaCalc!A18 -> 42-SS01BI-071517 - DUP | B10: =ChlaCalc!C18 -> 0.01 | C10: =ChlaCalc!H18 -> -0.062816999 | D10: =ChlaCalc!I18 -> -6.2816999 | E10: 42 | F10: 42931 | G10: Duplicate
A11: =ChlaCalc!A19 -> 53-SS01LU-alt2-071517 | B11: =ChlaCalc!C19 -> 6.925 | C11: =ChlaCalc!H19 -> 1.1586425 | D11: =ChlaCalc!I19 -> 0.16731299 | E11: 53 | F11: 42931 | G11: Sample
A12: =ChlaCalc!A20 -> 0-SS02BI-071717 | B12: =ChlaCalc!C20 -> 0.0008 | C12: =ChlaCalc!H20 -> 0.02851337 | D12: =ChlaCalc!I20 -> 35.641713 | E12: 0 | F12: 42933 | G12: Sample
A13: =ChlaCalc!A21 -> 6-SS02MI-071717 | B13: =ChlaCalc!C21 -> 0.79 | C13: =ChlaCalc!H21 -> -0.0020423645 | D13: =ChlaCalc!I21 -> -0.0025852716 | E13: 6 | F13: 42933 | G13: Sample
A14: =ChlaCalc!A22 -> 9-SS05MI-071717 | B14: =ChlaCalc!C22 -> 0.034 | C14: =ChlaCalc!H22 -> 0.03111181 | D14: =ChlaCalc!I22 -> 0.91505325 | E14: 9-alt | F14: 42933 | G14: Sample
A15: =ChlaCalc!A23 -> 23-SS05LI-072017 | B15: =ChlaCalc!C23 -> 0.01 | C15: =ChlaCalc!H23 -> -0.048092503 | D15: =ChlaCalc!I23 -> -4.8092503 | E15: 23 | F15: 42936 | G15: Sample
A16: =ChlaCalc!A24 -> 37-SS04OI-072017 | B16: =ChlaCalc!C24 -> 0.05 | C16: =ChlaCalc!H24 -> -0.037674682 | D16: =ChlaCalc!I24 -> -0.75349364 | E16: 37 | F16: 42936 | G16: Sample
A17: =ChlaCalc!A25 -> 24-SS06LU-072017 | B17: =ChlaCalc!C25 -> 8 | C17: =ChlaCalc!H25 -> 0.67533256 | D17: =ChlaCalc!I25 -> 0.08441657 | E17: 24 | F17: 42936 | G17: Sample
A18: =ChlaCalc!A26 -> 29-SS04LU-072017 | B18: =ChlaCalc!C26 -> 1.5 | C18: =ChlaCalc!H26 -> 0.37975996 | D18: =ChlaCalc!I26 -> 0.25317331 | E18: 29 | F18: 42936 | G18: Sample
A19: =ChlaCalc!A27 -> 35-SS02OI-072017 | B19: =ChlaCalc!C27 -> 0.216 | C19: =ChlaCalc!H27 -> 0.19081966 | D19: =ChlaCalc!I27 -> 0.88342434 | E19: 35 | F19: 42936 | G19: Sample
A20: =ChlaCalc!A28 -> 36-SS03OI-072017 | B20: =ChlaCalc!C28 -> 1.5 | C20: =ChlaCalc!H28 -> 0.41390058 | D20: =ChlaCalc!I28 -> 0.27593372 | E20: 36 | F20: 42936 | G20: Sample
A21: =ChlaCalc!A29 -> 38-SS01OI-072017 | B21: =ChlaCalc!C29 -> 0.018 | C21: =ChlaCalc!H29 -> -0.0056031903 | D21: =ChlaCalc!I29 -> -0.31128835 | E21: 38 | F21: 42936 | G21: Sample
A22: =ChlaCalc!A30 -> BLANK1-072017-TRAVEL | B22: =ChlaCalc!C30 -> 0.1 | C22: =ChlaCalc!H30 -> -0.078431701 | D22: =ChlaCalc!I30 -> -0.78431701 | E22: BL | F22: 42936 | G22: Field Blank
A23: =ChlaCalc!A31 -> 3-SS04BU-072217 | B23: =ChlaCalc!C31 -> 1.5 | C23: =ChlaCalc!H31 -> 0.14965362 | D23: =ChlaCalc!I31 -> 0.099769083 | E23: 3 | F23: 42938 | G23: Sample
A24: =ChlaCalc!A32 -> 8-SS04MI-072217 | B24: =ChlaCalc!C32 -> 1.5 | C24: =ChlaCalc!H32 -> 0.45408017 | D24: =ChlaCalc!I32 -> 0.30272011 | E24: 8 | F24: 42938 | G24: Sample
A25: =ChlaCalc!A33 -> 5-SS01MI-072217 | B25: =ChlaCalc!C33 -> 0.004 | C25: =ChlaCalc!H33 -> -0.066065049 | D25: =ChlaCalc!I33 -> -16.516262 | E25: 5 | F25: 42938 | G25: Sample
A26: =ChlaCalc!A34 -> 5-SS01MI-072217-DUP | B26: =ChlaCalc!C34 -> 0.004 | C26: =ChlaCalc!H34 -> -0.063346311 | D26: =ChlaCalc!I34 -> -15.836578 | E26: 5 | F26: 42938 | G26: Duplicate
A27: =ChlaCalc!A35 -> 10-SS06MI-072217 | B27: =ChlaCalc!C35 -> 0.004 | C27: =ChlaCalc!H35 -> -0.05747576 | D27: =ChlaCalc!I35 -> -14.36894 | E27: 10 | F27: 42938 | G27: Sample
A28: =ChlaCalc!A36 -> 10-SS06MI-072217-DUP | B28: =ChlaCalc!C36 -> 0.004 | C28: =ChlaCalc!H36 -> -0.059256173 | D28: =ChlaCalc!I36 -> -14.814043 | E28: 10 | F28: 42938 | G28: Duplicate
A29: =ChlaCalc!A37 -> 14-SS03MU-072217* | B29: =ChlaCalc!C37 -> 0.3 | C29: =ChlaCalc!H37 -> 0.26679998 | D29: =ChlaCalc!I37 -> 0.88933327 | E29: 14 | F29: 42938 | G29: Sample
A30: =ChlaCalc!A38 -> 14-SS03MU-072217-DUP* | B30: =ChlaCalc!C38 -> 0.27 | C30: =ChlaCalc!H38 -> 0.22835269 | D30: =ChlaCalc!I38 -> 0.84575069 | E30: 14 | F30: 42938 | G30: Duplicate
A31: =ChlaCalc!A39 -> 19-SS01LI-072217 | B31: =ChlaCalc!C39 -> 0.023 | C31: =ChlaCalc!H39 -> -0.041018971 | D31: =ChlaCalc!I39 -> -1.7834335 | E31: 19 | F31: 42938 | G31: Sample
A32: =ChlaCalc!A40 -> 19-SS01LI-072217-DUP | B32: =ChlaCalc!C40 -> 0.022 | C32: =ChlaCalc!H40 -> -0.047081998 | D32: =ChlaCalc!I40 -> -2.1400908 | E32: 19 | F32: 42938 | G32: Duplicate
A33: =ChlaCalc!A41 -> 20-SS02LI-072217 | B33: =ChlaCalc!C41 -> 0.004 | C33: =ChlaCalc!H41 -> -0.05685021 | D33: =ChlaCalc!I41 -> -14.212552 | E33: 20 | F33: 42938 | G33: Sample
A34: =ChlaCalc!A42 -> 20-SS02LI-072217-DUP | B34: =ChlaCalc!C42 -> 0.004 | C34: =ChlaCalc!H42 -> -0.056489315 | D34: =ChlaCalc!I42 -> -14.122329 | E34: 20 | F34: 42938 | G34: Duplicate
A35: =ChlaCalc!A43 -> SC-3B-072717 | B35: =ChlaCalc!C43 -> 0.022 | C35: =ChlaCalc!H43 -> -0.059496769 | D35: =ChlaCalc!I43 -> -2.7043986 | E35: SC-3B | F35: 42943 | G35: Sample
A36: =ChlaCalc!A44 -> DC-3-072715 | B36: =ChlaCalc!C44 -> 0.01 | C36: =ChlaCalc!H44 -> -0.016742801 | D36: =ChlaCalc!I44 -> -1.6742801 | E36: DC-3 | F36: 42943 | G36: Sample
A37: =ChlaCalc!A45 -> DC-4-072717 | B37: =ChlaCalc!C45 -> 0.024 | C37: =ChlaCalc!H45 -> -0.017945782 | D37: =ChlaCalc!I45 -> -0.74774093 | E37: DC-4 | F37: 42943 | G37: Sample
A38: =ChlaCalc!A46 -> 31-SS02FU-072917 | B38: =ChlaCalc!C46 -> 1.5 | C38: =ChlaCalc!H46 -> -0.065271081 | D38: =ChlaCalc!I46 -> -0.043514054 | E38: 31 | F38: 42945 | G38: Sample
A39: =ChlaCalc!A47 -> 32-SS03FU-072917 | B39: =ChlaCalc!C47 -> 1.5 | C39: =ChlaCalc!H47 -> 0.012826489 | D39: =ChlaCalc!I47 -> 0.0085509926 | E39: 32 | F39: 42945 | G39: Sample
A40: =ChlaCalc!A48 -> 7-SS03MI-073017 | B40: =ChlaCalc!C48 -> 0.019 | C40: =ChlaCalc!H48 -> -0.076651288 | D40: =ChlaCalc!I48 -> -4.0342783 | E40: 7 | F40: 42946 | G40: Sample
...

Sheet ChlaSummary
A1: *assuming negative values are 0 | D1: Scott's overlap samples
D2: *negatives removed below | F2: Duplicates
A3: # | B3: Sample ID | C3: Chla Conc. (ug/L) | D3: Chla Conc. (ug/L) | F3: DUP # | G3: Sample ID | H3: Conc. 1 (ug/L) | I3: Conc. 2 (ug/L) | J3: Mean (ug/L) | K3: Stdev (ug/L) | L3: Coeff V. (%)
A4: 1 | B4: =ChlaCalc!A10 -> StonyCreek-071017 | C4: =ChlaCalc!J10 -> 0 | D4: =IF(C4<0, 0, C4) -> 0 | F4: 1 | G4: =B4 -> StonyCreek-071017 | H4: =C4 -> 0 | I4: =C5 -> 0 | J4: =AVERAGE(H4:I4) -> 0 | K4: =STDEV(H4:I4) -> 0 | L4: =ABS(K4/J4) -> #DIV/0!
A5: 2 | B5: =ChlaCalc!A11 -> StonyCreek-071017-DUP | C5: =ChlaCalc!J11 -> 0 | D5: =IF(C5<0, 0, C5) -> 0 | F5: 2 | G5: =B11 -> 42-SS01BI-071517 | H5: =C11 -> 0 | I5: =C12 -> 0 | J5: =AVERAGE(H5:I5) -> 0 | K5: =STDEV(H5:I5) -> 0 | L5: =ABS(K5/J5) -> #DIV/0!
A6: 3 | B6: =ChlaCalc!A12 -> 27-SS02LU-071217 | C6: =ChlaCalc!J12 -> 0 | D6: =IF(C6<0, 0, C6) -> 0 | F6: 3 | G6: =B27 -> 5-SS01MI-072217 | H6: =C27 -> 0 | I6: =C28 -> 0 | J6: =AVERAGE(H6:I6) -> 0 | K6: =STDEV(H6:I6) -> 0 | L6: =ABS(K6/J6) -> #DIV/0!
A7: 4 | B7: =ChlaCalc!A13 -> 48-SS08LI-071217 | C7: =ChlaCalc!J13 -> 0 | D7: =IF(C7<0, 0, C7) -> 0 | F7: 4 | G7: =B29 -> 10-SS06MI-072217 | H7: =C29 -> 0 | I7: =C30 -> 0 | J7: =AVERAGE(H7:I7) -> 0 | K7: =STDEV(H7:I7) -> 0 | L7: =ABS(K7/J7) -> #DIV/0!
A8: 5 | B8: =ChlaCalc!A14 -> 13-SS02MU-071317 | C8: =ChlaCalc!J14 -> 0 | D8: =IF(C8<0, 0, C8) -> 0 | F8: 5 | G8: =B31 -> 14-SS03MU-072217* | H8: =C31 -> 0 | I8: =C32 -> 0 | J8: =AVERAGE(H8:I8) -> 0 | K8: =STDEV(H8:I8) -> 0 | L8: =ABS(K8/J8) -> #DIV/0!
A9: 6 | B9: =ChlaCalc!A15 -> 26-SS01LU-071417 | C9: =ChlaCalc!J15 -> 0 | D9: =IF(C9<0, 0, C9) -> 0 | F9: 6 | G9: =B33 -> 19-SS01LI-072217 | H9: =C33 -> 0 | I9: =C34 -> 0 | J9: =AVERAGE(H9:I9) -> 0 | K9: =STDEV(H9:I9) -> 0 | L9: =ABS(K9/J9) -> #DIV/0!
A10: 7 | B10: =ChlaCalc!A16 -> 30-SS01FU-071417 | C10: =ChlaCalc!J16 -> 0 | D10: =IF(C10<0, 0, C10) -> 0 | F10: 7 | G10: =B35 -> 20-SS02LI-072217 | H10: =C35 -> 0 | I10: =C36 -> 0 | J10: =AVERAGE(H10:I10) -> 0 | K10: =STDEV(H10:I10) -> 0 | L10: =ABS(K10/J10) -> #DIV/0!
A11: 8 | B11: =ChlaCalc!A17 -> 42-SS01BI-071517 | C11: =ChlaCalc!J17 -> 0 | D11: =IF(C11<0, 0, C11) -> 0 | F11: 8 | G11: =B49 -> StonyCreek-080717 | H11: =C49 -> 0 | I11: =C50 -> 0 | J11: =AVERAGE(H11:I11) -> 0 | K11: =STDEV(H11:I11) -> 0 | L11: =ABS(K11/J11) -> #DIV/0!
A12: 9 | B12: =ChlaCalc!A18 -> 42-SS01BI-071517 - DUP | C12: =ChlaCalc!J18 -> 0 | D12: =IF(C12<0, 0, C12) -> 0
A13: 10 | B13: =ChlaCalc!A19 -> 53-SS01LU-alt2-071517 | C13: =ChlaCalc!J19 -> 0 | D13: =IF(C13<0, 0, C13) -> 0
A14: 11 | B14: =ChlaCalc!A20 -> 0-SS02BI-071717 | C14: =ChlaCalc!J20 -> 0 | D14: =IF(C14<0, 0, C14) -> 0
A15: 13 | B15: =ChlaCalc!A21 -> 6-SS02MI-071717 | C15: =ChlaCalc!J21 -> 0 | D15: =IF(C15<0, 0, C15) -> 0
A16: 14 | B16: =ChlaCalc!A22 -> 9-SS05MI-071717 | C16: =ChlaCalc!J22 -> 0 | D16: =IF(C16<0, 0, C16) -> 0
A17: 15 | B17: =ChlaCalc!A23 -> 23-SS05LI-072017 | C17: =ChlaCalc!J23 -> 0 | D17: =IF(C17<0, 0, C17) -> 0
A18: 17 | B18: =ChlaCalc!A24 -> 37-SS04OI-072017 | C18: =ChlaCalc!J24 -> 0 | D18: =IF(C18<0, 0, C18) -> 0
A19: 18 | B19: =ChlaCalc!A25 -> 24-SS06LU-072017 | C19: =ChlaCalc!J25 -> 0 | D19: =IF(C19<0, 0, C19) -> 0
A20: 19 | B20: =ChlaCalc!A26 -> 29-SS04LU-072017 | C20: =ChlaCalc!J26 -> 0 | D20: =IF(C20<0, 0, C20) -> 0
A21: 20 | B21: =ChlaCalc!A27 -> 35-SS02OI-072017 | C21: =ChlaCalc!J27 -> 0 | D21: =IF(C21<0, 0, C21) -> 0
A22: 21 | B22: =ChlaCalc!A28 -> 36-SS03OI-072017 | C22: =ChlaCalc!J28 -> 0 | D22: =IF(C22<0, 0, C22) -> 0
A23: 22 | B23: =ChlaCalc!A29 -> 38-SS01OI-072017 | C23: =ChlaCalc!J29 -> 0 | D23: =IF(C23<0, 0, C23) -> 0
... A52: 51 | B52: =ChlaCalc!A58 -> 40-SS02BU-alt1-080917 | C52: =ChlaCalc!J58 -> 0 | D52: =IF(C52<0, 0, C52) -> 0
